<robot xmlns:xacro="http://www.ros.org/wiki/xacro">

    <xacro:include filename="$(find rm_description)/urdf/balance/momentum_block.urdf.xacro"/>

    <!-- https://upload.wikimedia.org/wikipedia/commons/5/52/Wheelbase_and_Track.png -->
    <xacro:property name="wheel_base" value="0.420"/>
    <xacro:property name="wheel_z_offset" value="0"/>
    <xacro:property name="wheel_joint_effort" value="5"/>
    <xacro:property name="wheel_joint_velocity" value="50"/>

    <xacro:macro name="wheel"
                 params="connected_to prefix wheel_x_offset wheel_y_offset wheel_z_offset  mechanical_reduction">
        <link name="${prefix}_wheel">
            <visual>
                <origin xyz="0 0 0" rpy="0 0 0"/>
                <geometry>
                    <mesh filename="package://rm_description/meshes/balance/wheel.stl" scale="0.001 .001 0.001"/>
                </geometry>
            </visual>
            <collision>
                <origin xyz="0 0 0" rpy="0 0 0"/>
                <geometry>
                    <mesh filename="package://rm_description/meshes/balance/wheel.stl" scale="0.001 .001 0.001"/>
                </geometry>
            </collision>
            <inertial>
                <mass value="0.72"/>
                <origin xyz="0 0 0"/>
                <inertia ixx="9.115e-3" ixy="-1513.324e-9" ixz="-4566.397e-9" iyy="1.683e-2"
                         iyz="-1.382e-4" izz="9.470e-3"/>
            </inertial>
        </link>

        <joint name="${prefix}_wheel_joint" type="revolute">
            <axis xyz="0 1 0"/>
            <origin xyz="${wheel_x_offset} ${wheel_y_offset} ${wheel_z_offset}" rpy="0 0 0"/>
            <parent link="${connected_to}"/>
            <child link="${prefix}_wheel"/>
            <limit effort="${wheel_joint_effort}" velocity="${wheel_joint_velocity}" lower="-1e16" upper="1e16"/>
        </joint>

        <transmission name="${prefix}_wheel_joint_trans">
            <type>transmission_interface/SimpleTransmission</type>
            <actuator name="${prefix}_wheel_joint_motor">
                <mechanicalReduction>${mechanical_reduction}</mechanicalReduction>
            </actuator>
            <joint name="${prefix}_wheel_joint">
                <hardwareInterface>hardware_interface/EffortJointInterface</hardwareInterface>
            </joint>
        </transmission>
    </xacro:macro>

    <xacro:macro name="chassis">
        <link name="base_link">
            <inertial>
                <mass value="10.098"/>
                <origin xyz="0.007 -0.001 0.039"/>
                <inertia ixx="2.398e-1" ixy="-1.144e-3" ixz="3.641e-3" iyy="1.639e-1"
                         iyz="1.525e-4" izz="3.255e-1"/>
            </inertial>
            <visual>
                <origin xyz="0 0 0" rpy="0 0 0"/>
                <geometry>
                    <mesh filename="package://rm_description/meshes/balance/base_link.stl" scale="0.001 .001 0.001"/>
                </geometry>
            </visual>
            <collision>
                <origin xyz="0 0 0" rpy="0 0 0"/>
                <geometry>
                    <mesh filename="package://rm_description/meshes/balance/base_link.stl" scale="0.001 .001 0.001"/>
                </geometry>
            </collision>
        </link>

        <xacro:momentum_block prefix="left" reflect="1" connected_to="base_link" x_offset="0" y_offset="0.16"
                              z_offset="0.0815"
                              mechanical_reduction="22.22"/>
        <xacro:momentum_block prefix="right" reflect="-1" connected_to="base_link" x_offset="0" y_offset="-0.16"
                              z_offset="0.0815"
                              mechanical_reduction="-22.22"/>
        <xacro:wheel connected_to="base_link" prefix="left" wheel_x_offset="0" wheel_y_offset="${wheel_base/2}"
                     wheel_z_offset="${wheel_z_offset}" mechanical_reduction="19.2032"/>
        <xacro:wheel connected_to="base_link" prefix="right" wheel_x_offset="0" wheel_y_offset="${-wheel_base/2}"
                     wheel_z_offset="${wheel_z_offset}" mechanical_reduction="-19.2032"/>

    </xacro:macro>

</robot>
